Workbook

Sheet Feature Matrix
A1: ID | B1: Feature | C1: Frontend Work Required | D1: Backend Work Required | E1: AI/ML Work Required | F1: Data & Storage Work Required | G1: Owner (Part 4 split)
A2: M1 | B2: Document Ingestion & Preprocessing | C2: NO — Internal pipeline stage; D5's admin panel is the only UI surface, and it triggers this rather than being part of it. | D2: YES — Ingestion job orchestration triggered from D5's admin panel or X4's scheduled crawler; queued via Redis/BullMQ so large runs don't block the request thread; writes job-status updates D5 polls; unit-of-work pattern grouping DB writes per ingestion run so a partial failure doesn't leave orphaned chunks. | E2: YES — Text extraction from BIS's HTML/PDF sources (unstructured or PyMuPDF) with structure parsing (headings/sections/tables) so M2's chunking respects document structure. Scope is explicitly the openly-published pages - standards catalogue/search, product-cert scheme pages, licensing/certification procedure pages, FAQs, circulars, hallmarking pages - not paywalled full clause text. Read bis.gov.in/robots.txt and its terms-of-use before writing any crawler code. | F2: YES — Raw document storage (object-storage reference + metadata: source URL, ingest date, checksum for idempotent re-crawls); parsed-structure cache so M2 doesn't re-parse on every run. | G2: Person 4
A3: M2 | B3: Chunking & Embedding Pipeline | C3: NO — Internal pipeline stage. | D3: NO — Almost entirely AI/ML + DB work; invoked by M1's job trigger and X4's incremental updates, no general backend logic of its own. | E3: YES — Chunking strategy (fixed-size vs. semantic/recursive via LangChain/LlamaIndex text splitters) with overlap tuning to preserve context across boundaries; embedding-model selection (local sentence-transformers vs. a hosted API model - a real cost/latency tradeoff, see Budget notes in Legend); deduplication of near-identical chunks across sources. | F3: YES — pgvector schema (one Postgres instance doubling as relational store + vector index - no separate vector DB unless pgvector becomes a real bottleneck); embeddings stored alongside relational chunk metadata (doc ID, section, source URL); disaster-recovery plan for the vector index (rebuild-from-source). | G3: Person 4 (+ Person 6 – data schema)
A4: M3 | B4: Vector Search / Semantic Retrieval | C4: NO — Internal; consumed transitively via D1 (chat) and D2 (browser, as metadata-filtered search). | D4: YES — Query orchestration and timeout/retry handling on the vector-DB call; result-set assembly for M5 - light backend scope. | E4: YES — HNSW vs. IVF index-type tradeoffs on pgvector; hybrid search combining vector similarity with keyword/BM25 (the explicit fallback for exact IS-number lookups vector search handles poorly); reranking retrieved chunks before generation; metadata filtering by document type/date/category (shared with D2). | F4: YES — pgvector index build/maintenance; query-time recall/latency tuning; load-test with concurrent sessions before the demo, per the risk register. Full-text search indexing shared with D2's standards browser. | G4: Person 5
A5: M4 | B5: Query Understanding | C5: NO — Internal pipeline stage. | D5: NO — Pure NLP logic. | E5: YES — Intent classification across the four defined intents (standard lookup, certification process, licensing, general query) via a rule engine or lightweight classifier; named-entity extraction (product category, IS number) to filter/boost retrieval and feed M7's taxonomy. | F5: NO — Extraction results are ephemeral, scoped to a single request. | G5: Person 5
A6: M5 | B6: RAG Answer Generation | C6: NO — Internal; streamed to the user via D1's SSE client. | D6: YES — Server-Sent Events streaming to the frontend; circuit-breaker pattern and retry-with-backoff around the LLM API call; an LLM-provider abstraction layer so the provider can be swapped without a rewrite; centralized logging for LLM call tracing/debugging. | E6: YES — Prompt construction with retrieved-context injection; prompt template management and versioning (shared with X2); semantic caching of near-duplicate queries to cut cost (shared with P3). The system prompt must treat both retrieved chunks and user input strictly as data, never as instructions - the core prompt-injection defense for the whole system. | F6: NO — Optionally logs prompt version + retrieved chunk IDs per answer, feeding the evaluation harness (see Legend). | G6: Person 5
A7: M6 | B7: Citation & Source Linking | C7: NO — Rendered by D1's citation chips and D3's viewer. | D7: NO — Logic lives entirely in the AI/ML layer. | E7: YES — Grounding/citation enforcement in generation - attaches every answer with the specific standard number, section, and source link it was drawn from; citation-formatting as a pure transformation function for a consistent, testable output shape. | F7: YES — Chunk metadata schema (doc ID, section, source URL) captured at ingestion (M1/M2) and read here at generation time - the schema D3 also reads from. | G7: Person 5
A8: M7 | B8: Product-to-Standard Recommendation | C8: NO — Exposed via D1 (free-text) and D9's guided wizard. | D8: NO — No general backend logic beyond invocation. | E8: YES — Product classification taxonomy design (shared with D9's wizard structure); matching logic between a plain-language product description and applicable Indian Standards via classification plus retrieval, ranked by confidence. | F8: YES — Taxonomy table and product-to-standard mapping table, curated rather than purely learned - light DB scope. | G8: Person 5
A9: M8 | B9: Confidence Scoring & Fallback | C9: NO — Surfaced via X3's escalation UI or a low-confidence badge in D1. | D9: NO — No general backend logic beyond invocation. | E9: YES — Confidence/uncertainty estimation from retrieval scores; pure-function design for the scoring itself; configurable retrieval-threshold tuning (shared with X2) - below threshold, the assistant declines and redirects to the BIS helpdesk instead of guessing. Tune conservatively specifically for demo day per the risk register. | F9: NO — Score computed per-request; optionally logged if a gap-analytics feature is built later. | G9: Person 5
A10: M9 | B10: Conversation Session Management | C10: YES — Reconnect logic on a dropped SSE/WebSocket; session heartbeat/keepalive handling so a multi-turn follow-up ("what about hallmarking for that one?") still resolves after a brief disconnect. | D10: YES — WebSocket/SSE session management for live chat; connection lifecycle management (open/close/reconnect); maps a connection to conversation_id + user session; handles multiple concurrent tabs per user. | E10: NO — Maintains context state for M4/M5 to consume; the multi-turn resolution itself is M4's intent/entity extraction working against session history, not this feature. | F10: YES — Session state, Redis-backed given Redis is already in the stack for BullMQ (ephemeral, not Postgres-persisted). | G10: Person 3
A11: D1 | B11: Conversational Chat Interface | C11: YES — Mobile-first chat UI (component-based, Zustand state); streaming answer rendering token-by-token via the SSE client; optimistic UI for sent messages; inline citation-chip rendering; skeleton loading states; error-boundary handling; responsive breakpoints; accessibility (screen reader, contrast). | D11: YES — Endpoint to accept a new message and create a placeholder assistant row; SSE gateway proxying the token stream from the FastAPI RAG service; persists user message on send and assistant message on stream completion; per-message auth + rate-limit check (P1). | E11: NO — Pure transport/rendering layer for M3-M6's output; owns no retrieval or generation logic itself. | F11: YES — Conversation & message schema (conversation_id, message_id, role, content, citations, created_at); FK to user; index on conversation_id for history pagination (shared with D4). | G11: Person 1
A12: D2 | B12: Standards Browser & Search | C12: YES — Traditional keyword/browse view for users who'd rather scan than chat; debounced search/autocomplete; virtualized results list. | D12: YES — Search endpoint layered on M3's hybrid vector+BM25 retrieval plus dedicated metadata filtering (by document type/date/category) for browse-style exact lookups; Redis cache for popular queries. | E12: NO — Consumes M3's hybrid search as a client; owns no retrieval logic of its own beyond filter parameters. | F12: YES — Full-text search indexing shared with M3; standards metadata table (IS number, title, category, status). | G12: Person 2
... A54: G18 | B54: .gov.in / NIC Hosting | C54: NO | D54: NO — Deployment/infra decision for the ministry-coordinated development phase, not the hackathon build. | E54: NO | F54: NO | G54: Person 6 (post-hackathon)

Sheet Summary by Category
A1: Category | B1: Features | C1: Frontend (Yes) | D1: Backend (Yes) | E1: AI/ML (Yes) | F1: Data & Storage (Yes)
A2: M - Mandatory Core | B2: =SUMPRODUCT((LEFT('Feature Matrix'!$A$2:$A$54,1)="M")*1) -> 9 | C2: =SUMPRODUCT((LEFT('Feature Matrix'!$A$2:$A$54,1)="M")*(LEFT('Feature Matrix'!$C$2:$C$54,3)="YES")) -> 1 | D2: =SUMPRODUCT((LEFT('Feature Matrix'!$A$2:$A$54,1)="M")*(LEFT('Feature Matrix'!$D$2:$D$54,3)="YES")) -> 4 | E2: =SUMPRODUCT((LEFT('Feature Matrix'!$A$2:$A$54,1)="M")*(LEFT('Feature Matrix'!$E$2:$E$54,3)="YES")) -> 8 | F2: =SUMPRODUCT((LEFT('Feature Matrix'!$A$2:$A$54,1)="M")*(LEFT('Feature Matrix'!$F$2:$F$54,3)="YES")) -> 6
A3: D - Dashboard/UI | B3: =SUMPRODUCT((LEFT('Feature Matrix'!$A$2:$A$54,1)="D")*1) -> 10 | C3: =SUMPRODUCT((LEFT('Feature Matrix'!$A$2:$A$54,1)="D")*(LEFT('Feature Matrix'!$C$2:$C$54,3)="YES")) -> 10 | D3: =SUMPRODUCT((LEFT('Feature Matrix'!$A$2:$A$54,1)="D")*(LEFT('Feature Matrix'!$D$2:$D$54,3)="YES")) -> 10 | E3: =SUMPRODUCT((LEFT('Feature Matrix'!$A$2:$A$54,1)="D")*(LEFT('Feature Matrix'!$E$2:$E$54,3)="YES")) -> 1 | F3: =SUMPRODUCT((LEFT('Feature Matrix'!$A$2:$A$54,1)="D")*(LEFT('Feature Matrix'!$F$2:$F$54,3)="YES")) -> 8
A4: X - Extraordinary/Differentiating | B4: =SUMPRODUCT((LEFT('Feature Matrix'!$A$2:$A$54,1)="X")*1) -> 12 | C4: =SUMPRODUCT((LEFT('Feature Matrix'!$A$2:$A$54,1)="X")*(LEFT('Feature Matrix'!$C$2:$C$54,3)="YES")) -> 5 | D4: =SUMPRODUCT((LEFT('Feature Matrix'!$A$2:$A$54,1)="X")*(LEFT('Feature Matrix'!$D$2:$D$54,3)="YES")) -> 7 | E4: =SUMPRODUCT((LEFT('Feature Matrix'!$A$2:$A$54,1)="X")*(LEFT('Feature Matrix'!$E$2:$E$54,3)="YES")) -> 8 | F4: =SUMPRODUCT((LEFT('Feature Matrix'!$A$2:$A$54,1)="X")*(LEFT('Feature Matrix'!$F$2:$F$54,3)="YES")) -> 6
A5: P - Supporting/Platform | B5: =SUMPRODUCT((LEFT('Feature Matrix'!$A$2:$A$54,1)="P")*1) -> 4 | C5: =SUMPRODUCT((LEFT('Feature Matrix'!$A$2:$A$54,1)="P")*(LEFT('Feature Matrix'!$C$2:$C$54,3)="YES")) -> 4 | D5: =SUMPRODUCT((LEFT('Feature Matrix'!$A$2:$A$54,1)="P")*(LEFT('Feature Matrix'!$D$2:$D$54,3)="YES")) -> 4 | E5: =SUMPRODUCT((LEFT('Feature Matrix'!$A$2:$A$54,1)="P")*(LEFT('Feature Matrix'!$E$2:$E$54,3)="YES")) -> 1 | F5: =SUMPRODUCT((LEFT('Feature Matrix'!$A$2:$A$54,1)="P")*(LEFT('Feature Matrix'!$F$2:$F$54,3)="YES")) -> 4
A6: G - Website Essentials (Added) | B6: =SUMPRODUCT((LEFT('Feature Matrix'!$A$2:$A$54,1)="G")*1) -> 18 | C6: =SUMPRODUCT((LEFT('Feature Matrix'!$A$2:$A$54,1)="G")*(LEFT('Feature Matrix'!$C$2:$C$54,3)="YES")) -> 11 | D6: =SUMPRODUCT((LEFT('Feature Matrix'!$A$2:$A$54,1)="G")*(LEFT('Feature Matrix'!$D$2:$D$54,3)="YES")) -> 7 | E6: =SUMPRODUCT((LEFT('Feature Matrix'!$A$2:$A$54,1)="G")*(LEFT('Feature Matrix'!$E$2:$E$54,3)="YES")) -> 0 | F6: =SUMPRODUCT((LEFT('Feature Matrix'!$A$2:$A$54,1)="G")*(LEFT('Feature Matrix'!$F$2:$F$54,3)="YES")) -> 5
A7: Total | B7: =SUM(B2:B6) -> 53 | C7: =SUM(C2:C6) -> 31 | D7: =SUM(D2:D6) -> 32 | E7: =SUM(E2:E6) -> 18 | F7: =SUM(F2:F6) -> 29

Sheet Legend & Notes
A1: Feature ID Prefixes (official catalog, Part 1)
A2: M# (9) | B2: Mandatory Core - the retrieval-and-answer engine itself.
A3: D# (10) | B3: Dashboard / UI features.
A4: X# (12) | B4: Extraordinary / Differentiating features - "this is what wins the room."
A5: P# (4) | B5: Supporting / Platform features.
A7: How to read the matrix
A8: YES (green) | B8: That layer needs dedicated work for this feature; the note explains what.
A9: NO (grey) | B9: That layer needs no new work - either out of scope, or the feature only consumes something another feature already owns (the note says which).
A10: ID cell color | B10: Matches the M/D/X/P category color used in the Summary by Category sheet.
A12: Scope risks that change what "in depth" actually means
A13: X1 - clause licensing | B13: Full clause-text of IS standards may not be legally scrapeable. Decision gate at Foundation phase: confirm what's actually usable before committing to full clause-level citation; fallback is standard number + title + scope + section heading.
A14: X2 - demo-critical | B14: Treated as mandatory-adjacent, not a stretch feature. A hallucinated answer live is the single worst failure mode for this problem statement. Needs a golden Q&A set (30-50 questions) and two tracked numbers: groundedness rate and decline rate.
A15: X6 - WhatsApp ToS | B15: Meta's WhatsApp Business terms (effective 15 Jan 2026) bar general-purpose AI assistants as the primary functionality of a presence. Scope X6 to structured, named intents with an explicit helpdesk handoff for open-ended queries - this is a build decision, not something already true by default.
A16: P2 - retention number | B16: A judge is likely to raise data-privacy for business details typed into chat. P2 needs a concrete, stated retention number before the pitch, not an abstract policy line.
A17: P3 - cost guardrails | B17: Build budget alerts from day one, not as a later feature - LLM API cost/rate-limit exposure is a named risk.
A18: M1/M3 - corpus scope | B18: MVP target is explicit: all FAQs and circulars, plus 3-5 product categories (electronics and food processing are the most citizen-legible starting points) - not the full ~24,000-standard catalogue. Load-test pgvector with concurrent sessions before the demo.
A20: Cross-cutting infrastructure (not tied to one feature)
A21: Data layer | B21: Relational schema for docs/chunks/conversations/users, migrations, and ORM setup are called out as "whole backend" in the spec, not owned by a single feature row above.
A22: DevOps | B22: Docker + Docker Compose for dev and the primary demo path; a single-node k3s manifest kept ready as a "here's how this scales" artifact for judges, without running the live demo on it; CI/CD via GitHub Actions.
A23: Security | B23: Prompt injection defense (treat retrieved chunks and user input as data, never instructions) sits inside M5. No full penetration test needed for a hackathon build - one Cross-Cutting paragraph plus a stated P2 retention number is enough to survive a judge's security question.
A24: Monitoring | B24: Basic structured logging + the P3 cost dashboard is enough for a hackathon MVP; skip a full Prometheus/Grafana buildout unless time allows.
A26: Build order (dependency-driven, from Part 5 + addendum gates)
A27: Gate 1 - Foundation | B27: DB schema (incl. pgvector), auth, API skeleton, one ingestion source working end-to-end (start with FAQs/circulars), minimal chat UI hitting a stubbed answer. If not true, nothing downstream should start.
A28: Gate 2 - Core RAG loop | B28: M1-M2 (ingestion/chunking/embedding), M3 (retrieval), M4 (query understanding), M5-M6 (grounded generation with citations), M8 (confidence fallback), basic chat UI (D1, D3). If grounding quality is poor here, stop adding features and fix retrieval first.
A29: Gate 3 - Product-matching & session depth | B29: M7 (product-to-standard), M9 (multi-turn sessions), D2 (browser), D4 (history), D5 (admin panel).
A30: Gate 4 - Differentiators | B30: Realistically pick 4-6 of the 12. Recommended set: X2 (cite-or-decline), X11 (plain-language explainer), X5 (checklist generator), X1 (deep linking, scoped to what's licensable), X8 (gap analytics), X6 (WhatsApp channel). All seven rehearsed demo queries should work live; backup video recorded.
A31: Gate 5 - Polish | B31: Remaining dashboard features (D6, D7, D9, D10), multi-language (D8), voice (X7), offline PWA (X9), ops status page (P4). Can slip without threatening the demo.
A33: Tech stack reference (Part 3)
A34: Frontend | B34: React 18 + TypeScript, Vite, TailwindCSS + shadcn/ui, Zustand (state), TanStack Query, react-i18next (English/Hindi), SSE client.
A35: Backend / orchestration | B35: Node.js + NestJS (TypeScript) - auth, sessions, conversation history, admin CRUD, rate limiting, WhatsApp webhook.
A36: AI / RAG microservice | B36: Python (FastAPI), kept deliberately thin - LangChain or LlamaIndex for ingestion/chunking/retrieval rather than hand-rolled logic. NestJS calls it over a simple internal REST API.
A37: Vector storage | B37: pgvector (Postgres extension) rather than a separate vector DB; move to Qdrant only if pgvector's performance becomes a real bottleneck in testing.
A38: Queue / cache | B38: Redis (BullMQ on the Node side) for ingestion jobs and semantic-answer caching.
A39: Auth | B39: JWT for the API, simple session cookies for the public chat - no full SSO/Keycloak needed.
A40: Messaging channel | B40: WhatsApp Business API (Cloud API) for X6.
A42: Source
A43: Derived from | B43: SAATHI - Master Build Specification & Internal Pitch (Parts 0-5) plus its addendum (Sections A-O), including the 27 Aug 2026 post-pitch fact-check (Section O). Verify the BMSCE-specific internal submission deadline and the WhatsApp/competing-tool findings independently before the pitch, per the source document's own caveats.
A45: G-series additions (G1–G18) — not part of the official SIH26107 catalog
A46: What this is | B46: 18 generic website-essentials items flagged as “Not Covered” on the Website Essentials Checklist sheet, now added to the Feature Matrix as G1–G18 with the same Frontend/Backend/AI-ML/Data&Storage breakdown and an assigned Owner.
A47: Important for the pitch | B47: G1–G18 are standard web-hygiene/compliance items (login recovery, ToS, CAPTCHA, sitemap, etc.), not part of Part 1's official 35-feature catalog (M/D/X/P) from the SIH26107 spec. Present the official 35 as the feature catalog to judges; treat G1–G18 as build-hygiene work the team should still do, not as differentiators.
...

Sheet Website Essentials Checklist
A1: # | B1: Category | C1: Website Element | D1: Description | E1: Status | F1: Mapped SAATHI Feature(s) | G1: Recommendation / Notes
A2: 1 | B2: Core User-Facing Pages | C2: Homepage | D2: Landing page introducing SAATHI and its purpose before entering the chat. | E2: Planned | F2: G1 | G2: Added to the Feature Matrix as G1, owned per the Owner column there. Add a simple landing page (what SAATHI is, who it's for, CTA into D1) sitting in front of the chat interface.
A3: 2 | B3: Core User-Facing Pages | C3: About Us Page | D3: Explains SAATHI, BIS, and the ministry backing — builds trust for a govt tool. | E3: Planned | F3: G2 | G3: Added to the Feature Matrix as G2, owned per the Owner column there. Add. Directly supports the 'ministry-trust' framing the pitch (Part 0) leans on.
A4: 3 | B4: Core User-Facing Pages | C4: Contact Us Page | D4: Standalone way to reach BIS outside the chat (phone/email/address). | E4: Partial | F4: X3 | G4: X3 escalates low-confidence queries to the helpdesk from inside chat, but a static contact page is still needed for users who never open the chat.
A5: 4 | B5: Core User-Facing Pages | C5: Services/Products Directory | D5: Catalog overview of what the site offers. | E5: Partial | F5: D2 | G5: D2's Standards Browser is the closest equivalent; consider an explicit 'what SAATHI can help with' overview above it.
A6: 5 | B6: Core User-Facing Pages | C6: Individual Detailing Page | D6: Deep-dive page for a single standard/service. | E6: Covered | F6: D3 | G6: D3 (Source/Citation Viewer) already serves this role.
A7: 6 | B7: Core User-Facing Pages | C7: Pricing / Plans Page | D7: Cost-tier comparison. | E7: N/A | F7: — | G7: Free government service — not applicable.
A8: 7 | B8: Core User-Facing Pages | C8: Testimonials / Reviews Page | D8: Customer success stories / social proof. | E8: Planned | F8: G3 | G8: Added to the Feature Matrix as G3, owned per the Owner column there. Optional. Low priority for a government utility, but a few MSME quotes post-launch could help adoption.
A9: 8 | B9: Core User-Facing Pages | C9: FAQ Page | D9: Static, browsable answers to common questions. | E9: Partial | F9: M1 | G9: M1 ingests BIS's own FAQs as chat content, but there's no static FAQ page about SAATHI itself (how it works, what it can't do, data privacy).
A10: 9 | B10: Core User-Facing Pages | C10: Blog / Resource Hub | D10: Article listing for content marketing / SEO. | E10: N/A | F10: — | G10: Out of scope for a hackathon MVP.
A11: 10 | B11: Core User-Facing Pages | C11: Individual Blog Post Page | D11: Single article layout. | E11: N/A | F11: — | G11: Out of scope.
A12: 11 | B12: Core User-Facing Pages | C12: Portfolio / Case Studies | D12: Gallery of past work. | E12: N/A | F12: — | G12: Not applicable — SAATHI has no 'past projects' to showcase.
A13: 12 | B13: Core User-Facing Pages | C13: Careers / Jobs Page | D13: Open positions + application form. | E13: N/A | F13: — | G13: Not applicable.
... A54: 53 | B54: India Government Web Standards (bonus — not in original list) | C54: .gov.in / NIC Hosting | D54: Official domain and hosting requirements for ministry-backed sites. | E54: Planned | F54: G18 | G54: Added to the Feature Matrix as G18, owned per the Owner column there. Only relevant once SAATHI moves past the hackathon demo into the ministry-coordinated development phase — not a build-week concern.
B56: Coverage Summary
B57: Status | C57: Count
B58: Covered | C58: =COUNTIF(E2:E54,"Covered") -> 12
B59: Partial | C59: =COUNTIF(E2:E54,"Partial") -> 14
B60: Planned (newly added, G1-G18) | C60: =COUNTIF(E2:E54,"Planned") -> 18
B61: Not Covered | C61: =COUNTIF(E2:E54,"Not Covered") -> 0
B62: N/A (Not Needed) | C62: =COUNTIF(E2:E54,"N/A") -> 9
B63: Total | C63: =SUM(C58:C62) -> 53
